<?xml version="1.0" ?>
<testsuite errors="11" failures="0" name="LogUserTest-2018_07_10_14_36_22" tests="12" time="24.535">
	<testcase classname="LogUserTest" name="test_06_admin_correct_login_and_password" time="4.517"/>
	<testcase classname="LogUserTest" name="test_01_correct_login_and_password" time="11.696">
		<error message="Message: 
" type="TimeoutException">
<![CDATA[Traceback (most recent call last):
  File "C:/Testy/Logowanie/LogTest.py", line 32, in test_01_correct_login_and_password
    assert self.account_page.check_login_result(self.testName)
  File "C:\Testy\Logowanie\Page\Account_page.py", line 14, in check_login_result
    self.login_page.log_result()
  File "C:\Testy\Logowanie\Page\Login_page.py", line 64, in log_result
    self.click_option_button()
  File "C:\Testy\Logowanie\Page\Login_page.py", line 51, in click_option_button
    self.option_button().click()
  File "C:\Testy\Logowanie\Page\Login_page.py", line 28, in option_button
    self.driver_commands.wait_for_element_by_css_selector(".fa-th")
  File "C:\Testy\Logowanie\Libs\Driver_commands.py", line 18, in wait_for_element_by_css_selector
    WebDriverWait(self.driver, 10).until(EC.presence_of_element_located((By.CSS_SELECTOR, element)))
  File "C:\Testy\Logowanie\venv\lib\site-packages\selenium\webdriver\support\wait.py", line 80, in until
    raise TimeoutException(message, screen, stacktrace)
selenium.common.exceptions.TimeoutException: Message: 

]]>		</error>
	</testcase>
	<testcase classname="LogUserTest" name="test_02_correct_login_invalid_password" time="0.960">
		<error message="" type="AssertionError">
<![CDATA[Traceback (most recent call last):
  File "C:/Testy/Logowanie/LogTest.py", line 39, in test_02_correct_login_invalid_password
    assert self.account_page.check_invalid_login_result(self.testName)
AssertionError
]]>		</error>
	</testcase>
	<testcase classname="LogUserTest" name="test_03_invalid_login_correct_password" time="0.852">
		<error message="" type="AssertionError">
<![CDATA[Traceback (most recent call last):
  File "C:/Testy/Logowanie/LogTest.py", line 46, in test_03_invalid_login_correct_password
    assert self.account_page.check_invalid_login_result(self.testName)
AssertionError
]]>		</error>
	</testcase>
	<testcase classname="LogUserTest" name="test_04_no_login_correct_password" time="0.953">
		<error message="" type="AssertionError">
<![CDATA[Traceback (most recent call last):
  File "C:/Testy/Logowanie/LogTest.py", line 53, in test_04_no_login_correct_password
    assert self.account_page.check_invalid_login_result(self.testName)
AssertionError
]]>		</error>
	</testcase>
	<testcase classname="LogUserTest" name="test_05_correct_login_no_password" time="1.142">
		<error message="" type="AssertionError">
<![CDATA[Traceback (most recent call last):
  File "C:/Testy/Logowanie/LogTest.py", line 60, in test_05_correct_login_no_password
    assert self.account_page.check_invalid_login_result(self.testName)
AssertionError
]]>		</error>
	</testcase>
	<testcase classname="LogUserTest" name="test_07_admin_correct_login_invalid_password" time="0.725">
		<error message="" type="AssertionError">
<![CDATA[Traceback (most recent call last):
  File "C:/Testy/Logowanie/LogTest.py", line 75, in test_07_admin_correct_login_invalid_password
    assert self.account_page.check_invalid_login_result(self.testName)
AssertionError
]]>		</error>
	</testcase>
	<testcase classname="LogUserTest" name="test_08_admin_invalid_login_correct_password" time="0.914">
		<error message="" type="AssertionError">
<![CDATA[Traceback (most recent call last):
  File "C:/Testy/Logowanie/LogTest.py", line 82, in test_08_admin_invalid_login_correct_password
    assert self.account_page.check_invalid_login_result(self.testName)
AssertionError
]]>		</error>
	</testcase>
	<testcase classname="LogUserTest" name="test_09_no_admin_login_correct_password" time="0.602">
		<error message="" type="AssertionError">
<![CDATA[Traceback (most recent call last):
  File "C:/Testy/Logowanie/LogTest.py", line 89, in test_09_no_admin_login_correct_password
    assert self.account_page.check_invalid_login_result(self.testName)
AssertionError
]]>		</error>
	</testcase>
	<testcase classname="LogUserTest" name="test_10_admin_correct_login_no_password" time="0.620">
		<error message="" type="AssertionError">
<![CDATA[Traceback (most recent call last):
  File "C:/Testy/Logowanie/LogTest.py", line 96, in test_10_admin_correct_login_no_password
    assert self.account_page.check_invalid_login_result(self.testName)
AssertionError
]]>		</error>
	</testcase>
	<testcase classname="LogUserTest" name="test_11_admin_login_user_password" time="0.851">
		<error message="" type="AssertionError">
<![CDATA[Traceback (most recent call last):
  File "C:/Testy/Logowanie/LogTest.py", line 103, in test_11_admin_login_user_password
    assert self.account_page.check_invalid_login_result(self.testName)
AssertionError
]]>		</error>
	</testcase>
	<testcase classname="LogUserTest" name="test_12_user_login_admin_password" time="0.702">
		<error message="" type="AssertionError">
<![CDATA[Traceback (most recent call last):
  File "C:/Testy/Logowanie/LogTest.py", line 110, in test_12_user_login_admin_password
    assert self.account_page.check_invalid_login_result(self.testName)
AssertionError
]]>		</error>
	</testcase>
	<system-out>
<![CDATA[]]>	</system-out>
	<system-err>
<![CDATA[]]>	</system-err>
</testsuite>
